<robot name="Wattson" version="1.0">
  <joint name="joint_head_pitch" type="revolute">
    <limit lower="0.00000" upper="0.00000" effort="0.00000" velocity="0.00000"/>
    <origin rpy="0.00000 -1.57080 0.00000" xyz="-0.00012 -0.00000 0.03998"/>
    <parent link="link_head_yaw"/>
    <child link="link_head_pitch"/>
    <axis xyz="0.00000 0.00000 1.00000"/>
  </joint>
  <joint name="joint_head_roll" type="revolute">
    <limit lower="0.00000" upper="0.00000" effort="0.00000" velocity="0.00000"/>
    <origin rpy="-1.57080 1.57080 0.00000" xyz="0.10002 -0.01200 0.00030"/>
    <parent link="link_head_pitch"/>
    <child link="link_head_roll"/>
    <axis xyz="0.00000 0.00000 1.00000"/>
  </joint>
  <joint name="joint_head_yaw" type="revolute">
    <limit lower="0.00000" upper="0.00000" effort="0.00000" velocity="0.00000"/>
    <origin rpy="0.00000 0.00000 0.00000" xyz="0.00012 0.00000 0.20400"/>
    <parent link="link_torso"/>
    <child link="link_head_yaw"/>
    <axis xyz="0.00000 0.00000 1.00000"/>
  </joint>
  <joint name="joint_left_arm_yaw" type="revolute">
    <limit lower="-3.14000" upper="3.14000" effort="0.00000" velocity="0.00000"/>
    <origin rpy="1.57080 0.00000 0.00000" xyz="-0.00020 0.12745 0.01486"/>
    <parent link="link_left_shoulder_x"/>
    <child link="link_left_upper_arm"/>
    <axis xyz="0.00000 0.00000 1.00000"/>
  </joint>
  <joint name="joint_left_elbow_pitch" type="revolute">
    <limit lower="-3.14000" upper="3.14000" effort="0.00000" velocity="0.00000"/>
    <origin rpy="-0.00000 1.57080 0.00000" xyz="0.00011 -0.00027 -0.23600"/>
    <parent link="link_left_upper_arm"/>
    <child link="link_left_forearm"/>
    <axis xyz="0.00000 0.00000 1.00000"/>
  </joint>
  <joint name="joint_left_forearm_yaw" type="revolute">
    <limit lower="-3.14000" upper="3.14000" effort="0.00000" velocity="0.00000"/>
    <origin rpy="-0.00000 -1.57080 0.00000" xyz="0.09363 0.00002 -0.00011"/>
    <parent link="link_left_forearm"/>
    <child link="link_left_wrist"/>
    <axis xyz="0.00000 0.00000 1.00000"/>
  </joint>
  <joint name="joint_left_shoulder_pitch" type="revolute">
    <limit lower="-3.14000" upper="3.14000" effort="0.00000" velocity="0.00000"/>
    <origin rpy="-3.14159 -1.04720 -0.00000" xyz="-0.16356 0.00077 0.19342"/>
    <parent link="link_torso"/>
    <child link="link_left_shoulder"/>
    <axis xyz="0.00000 0.00000 1.00000"/>
  </joint>
  <joint name="joint_left_shoulder_roll" type="revolute">
    <limit lower="-3.14000" upper="3.14000" effort="0.00000" velocity="0.00000"/>
    <origin rpy="1.57080 -1.04720 0.00000" xyz="0.00011 0.00077 -0.10785"/>
    <parent link="link_left_shoulder"/>
    <child link="link_left_shoulder_x"/>
    <axis xyz="0.00000 0.00000 1.00000"/>
  </joint>
  <joint name="joint_left_wrist_pitch" type="revolute">
    <limit lower="-3.14000" upper="3.14000" effort="0.00000" velocity="0.00000"/>
    <origin rpy="-0.00000 1.57080 0.00000" xyz="0.00110 -0.00019 -0.17400"/>
    <parent link="link_left_wrist"/>
    <child link="link_left_wrist_x"/>
    <axis xyz="0.00000 0.00000 1.00000"/>
  </joint>
  <joint name="joint_left_wrist_roll" type="revolute">
    <limit lower="-3.14000" upper="3.14000" effort="0.00000" velocity="0.00000"/>
    <origin rpy="2.42926 1.57080 -2.28313" xyz="0.00002 0.02290 0.00009"/>
    <parent link="link_left_wrist_x"/>
    <child link="link_left_hand"/>
    <axis xyz="0.00000 0.00000 1.00000"/>
  </joint>
  <joint name="joint_right_arm_yaw" type="revolute">
    <limit lower="-3.14000" upper="3.14000" effort="0.00000" velocity="0.00000"/>
    <origin rpy="1.57080 0.00000 0.00000" xyz="0.00750 -0.13650 0.00800"/>
    <parent link="link_right_shoulder_x"/>
    <child link="link_right_upper_arm"/>
    <axis xyz="0.00000 0.00000 1.00000"/>
  </joint>
  <joint name="joint_right_elbow_pitch" type="revolute">
    <limit lower="-3.14000" upper="3.14000" effort="0.00000" velocity="0.00000"/>
    <origin rpy="1.79848 -1.57080 1.34311" xyz="0.00800 -0.00750 0.13550"/>
    <parent link="link_right_upper_arm"/>
    <child link="link_right_forearm"/>
    <axis xyz="0.00000 0.00000 1.00000"/>
  </joint>
  <joint name="joint_right_forearm_yaw" type="revolute">
    <limit lower="-3.14000" upper="3.14000" effort="0.00000" velocity="0.00000"/>
    <origin rpy="-3.14159 -1.57080 0.00000" xyz="0.12550 -0.00750 -0.00800"/>
    <parent link="link_right_forearm"/>
    <child link="link_right_wrist"/>
    <axis xyz="0.00000 0.00000 1.00000"/>
  </joint>
  <joint name="joint_right_shoulder_pitch" type="revolute">
    <limit lower="-3.14000" upper="3.14000" effort="0.00000" velocity="0.00000"/>
    <origin rpy="-0.00000 1.57080 0.00000" xyz="0.16554 0.00000 0.17223"/>
    <parent link="link_torso"/>
    <child link="link_right_shoulder"/>
    <axis xyz="0.00000 0.00000 1.00000"/>
  </joint>
  <joint name="joint_right_shoulder_roll" type="revolute">
    <limit lower="-3.14000" upper="3.14000" effort="0.00000" velocity="0.00000"/>
    <origin rpy="1.57080 -1.57080 0.00000" xyz="0.00750 0.00800 0.09550"/>
    <parent link="link_right_shoulder"/>
    <child link="link_right_shoulder_x"/>
    <axis xyz="0.00000 0.00000 1.00000"/>
  </joint>
  <joint name="joint_right_wrist_roll" type="revolute">
    <limit lower="-3.14000" upper="3.14000" effort="0.00000" velocity="0.00000"/>
    <origin rpy="-1.57080 0.00000 3.14159" xyz="0.00000 -0.03732 0.15088"/>
    <parent link="link_right_wrist"/>
    <child link="link_right_hand"/>
    <axis xyz="0.00000 0.00000 1.00000"/>
  </joint>
  <link name="link_head_pitch">
    <visual name="head_pitch">
      <origin rpy="-0.00000 1.57080 0.00000" xyz="0.00000 0.00000 0.00000"/>
      <material name="Opaque(160,160,160)"/>
      <geometry>
        <mesh filename="package://wattson_description/meshes/stl/head_pitch.stl" scale="1.00000 1.00000 1.00000"/>
      </geometry>
    </visual>
  </link>
  <link name="link_head_roll">
    <visual name="camera">
      <origin rpy="1.57080 0.00000 0.00000" xyz="-0.00620 -0.03059 0.03605"/>
      <material name="Plastic - Texture - Random (Black Gloss)"/>
      <geometry>
        <mesh filename="package://wattson_description/meshes/stl/camera.stl" scale="1.00000 1.00000 1.00000"/>
      </geometry>
    </visual>
    <visual name="head_roll">
      <origin rpy="1.57080 0.00000 0.00000" xyz="0.00000 0.00000 0.00000"/>
      <material name="Opaque(160,160,160)"/>
      <geometry>
        <mesh filename="package://wattson_description/meshes/stl/head_roll.stl" scale="1.00000 1.00000 1.00000"/>
      </geometry>
    </visual>
  </link>
  <link name="link_head_yaw">
    <visual name="head_yaw">
      <origin rpy="0.00000 0.00000 0.00000" xyz="0.00000 0.00000 0.00000"/>
      <material name="Opaque(25,25,25)"/>
      <geometry>
        <mesh filename="package://wattson_description/meshes/stl/head_yaw.stl" scale="1.00000 1.00000 1.00000"/>
      </geometry>
    </visual>
  </link>
  <link name="link_left_forearm">
    <collision>
      <origin rpy="-0.00000 -1.57080 0.00000" xyz="0.03558 -0.00583 0.00393"/>
      <geometry>
        <box size="0.08489 0.06853 0.11616"/>
      </geometry>
    </collision>
    <visual name="left_forearm">
      <origin rpy="-0.00000 -1.57080 0.00000" xyz="0.00000 0.00000 0.00000"/>
      <material name="Opaque(25,25,25)"/>
      <geometry>
        <mesh filename="package://wattson_description/meshes/stl/left_forearm.stl" scale="1.00000 1.00000 1.00000"/>
      </geometry>
    </visual>
  </link>
  <link name="link_left_hand">
    <collision>
      <origin rpy="1.57080 0.00000 3.14159" xyz="-0.00299 -0.11191 -0.03097"/>
      <geometry>
        <box size="0.03776 0.08957 0.26082"/>
      </geometry>
    </collision>
    <visual name="left_hand">
      <origin rpy="1.57080 0.00000 3.14159" xyz="0.00000 0.00000 0.00000"/>
      <material name="Opaque(160,160,160)"/>
      <geometry>
        <mesh filename="package://wattson_description/meshes/stl/left_hand.stl" scale="1.00000 1.00000 1.00000"/>
      </geometry>
    </visual>
  </link>
  <link name="link_left_shoulder">
    <collision>
      <origin rpy="0.00000 -0.00000 -1.57080" xyz="-0.00517 0.00077 -0.06157"/>
      <geometry>
        <cylinder radius="0.05040" length="0.11000"/>
      </geometry>
    </collision>
    <visual name="left_shoulder">
      <origin rpy="3.14159 -1.04720 0.00000" xyz="-0.00000 0.00000 0.00000"/>
      <material name="Opaque(25,25,25)"/>
      <geometry>
        <mesh filename="package://wattson_description/meshes/stl/left_shoulder.stl" scale="1.00000 1.00000 1.00000"/>
      </geometry>
    </visual>
  </link>
  <link name="link_left_shoulder_x">
    <collision>
      <origin rpy="1.57080 0.00000 -0.00000" xyz="-0.00020 0.05428 0.00895"/>
      <geometry>
        <box size="0.06396 0.10018 0.17240"/>
      </geometry>
    </collision>
    <visual name="left_shoulder_x">
      <origin rpy="1.57080 0.00000 0.00000" xyz="0.00000 0.00000 0.00000"/>
      <material name="Opaque(179,179,179)"/>
      <geometry>
        <mesh filename="package://wattson_description/meshes/stl/left_shoulder_x.stl" scale="1.00000 1.00000 1.00000"/>
      </geometry>
    </visual>
  </link>
  <link name="link_left_upper_arm">
    <collision>
      <origin rpy="0.00000 0.00000 0.00000" xyz="0.00473 -0.00127 -0.13299"/>
      <geometry>
        <box size="0.07946 0.06203 0.26602"/>
      </geometry>
    </collision>
    <visual name="left_upper_arm">
      <origin rpy="0.00000 0.00000 -0.00000" xyz="0.00000 0.00000 0.00000"/>
      <material name="Opaque(191,189,187)"/>
      <geometry>
        <mesh filename="package://wattson_description/meshes/stl/left_upper_arm.stl" scale="1.00000 1.00000 1.00000"/>
      </geometry>
    </visual>
  </link>
  <link name="link_left_wrist">
    <collision>
      <origin rpy="0.00000 0.00000 0.00000" xyz="-0.00130 -0.00313 -0.09773"/>
      <geometry>
        <box size="0.07085 0.08614 0.19550"/>
      </geometry>
    </collision>
    <visual name="left_wrist">
      <origin rpy="0.00000 0.00000 -0.00000" xyz="0.00000 0.00000 0.00000"/>
      <material name="Opaque(160,160,160)"/>
      <geometry>
        <mesh filename="package://wattson_description/meshes/stl/left_wrist.stl" scale="1.00000 1.00000 1.00000"/>
      </geometry>
    </visual>
  </link>
  <link name="link_left_wrist_x">
    <collision>
      <origin rpy="-0.00000 -1.57080 0.00000" xyz="-0.00775 -0.00002 -0.00201"/>
      <geometry>
        <box size="0.07164 0.08000 0.06454"/>
      </geometry>
    </collision>
    <visual name="left_wrist_x">
      <origin rpy="-0.00000 -1.57080 0.00000" xyz="0.00000 0.00000 0.00000"/>
      <material name="Opaque(25,25,25)"/>
      <geometry>
        <mesh filename="package://wattson_description/meshes/stl/left_wrist_x.stl" scale="1.00000 1.00000 1.00000"/>
      </geometry>
    </visual>
  </link>
  <link name="link_right_forearm">
    <collision>
      <origin rpy="0.00000 -1.57080 0.00000" xyz="0.03850 -0.00626 -0.00425"/>
      <geometry>
        <cylinder radius="0.05625" length="0.17200"/>
      </geometry>
    </collision>
    <visual name="right_forearm">
      <origin rpy="0.00000 -1.57080 0.00000" xyz="0.00000 0.00000 0.00000"/>
      <material name="Plastic - Matte (White)"/>
      <geometry>
        <mesh filename="package://wattson_description/meshes/stl/right_forearm.stl" scale="1.00000 1.00000 1.00000"/>
      </geometry>
    </visual>
  </link>
  <link name="link_right_hand">
    <visual name="Cone">
      <origin rpy="1.57080 0.00000 -3.14159" xyz="-0.00000 -0.03300 -0.04290"/>
      <material name="Right arrow"/>
      <geometry>
        <mesh filename="package://wattson_description/meshes/stl/Cone.stl" scale="0.01903 0.01903 0.04934"/>
      </geometry>
    </visual>
  </link>
  <link name="link_right_shoulder">
    <collision>
      <origin rpy="0.00000 0.00000 0.00000" xyz="0.00000 0.00000 0.07150"/>
      <geometry>
        <cylinder radius="0.06500" length="0.14300"/>
      </geometry>
    </collision>
    <visual name="right_shoulder">
      <origin rpy="0.00000 -1.57080 0.00000" xyz="0.00000 0.00000 0.00000"/>
      <material name="Stainless Steel - Satin"/>
      <geometry>
        <mesh filename="package://wattson_description/meshes/stl/right_shoulder.stl" scale="1.00000 1.00000 1.00000"/>
      </geometry>
    </visual>
  </link>
  <link name="link_right_shoulder_x">
    <collision>
      <origin rpy="-1.57080 0.00000 0.00000" xyz="0.00750 -0.04400 0.00800"/>
      <geometry>
        <cylinder radius="0.06000" length="0.18300"/>
      </geometry>
    </collision>
    <visual name="right_shoulder_x">
      <origin rpy="-1.57080 0.00000 0.00000" xyz="0.00000 0.00000 0.00000"/>
      <material name="Plastic - Matte (White)"/>
      <geometry>
        <mesh filename="package://wattson_description/meshes/stl/right_shoulder_x.stl" scale="1.00000 1.00000 1.00000"/>
      </geometry>
    </visual>
  </link>
  <link name="link_right_upper_arm">
    <collision>
      <origin rpy="3.14159 0.00000 0.00000" xyz="0.00000 0.00000 0.09150"/>
      <geometry>
        <cylinder radius="0.06000" length="0.18300"/>
      </geometry>
    </collision>
    <visual name="right_upper_arm">
      <origin rpy="3.14159 0.00000 0.00000" xyz="0.00000 -0.00000 0.00000"/>
      <material name="Plastic - Matte (White)"/>
      <geometry>
        <mesh filename="package://wattson_description/meshes/stl/right_upper_arm.stl" scale="1.00000 1.00000 1.00000"/>
      </geometry>
    </visual>
  </link>
  <link name="link_right_wrist">
    <collision>
      <origin rpy="3.14159 0.00000 0.00000" xyz="0.00000 0.00000 0.05488"/>
      <geometry>
        <cylinder radius="0.05250" length="0.10977"/>
      </geometry>
    </collision>
    <visual name="right_wrist">
      <origin rpy="3.14159 0.00000 0.00000" xyz="0.00000 -0.00000 0.00000"/>
      <material name="Plastic - Matte (White)"/>
      <geometry>
        <mesh filename="package://wattson_description/meshes/stl/right_wrist.stl" scale="1.00000 1.00000 1.00000"/>
      </geometry>
    </visual>
  </link>
  <link name="link_torso">
    <collision>
      <origin rpy="3.14159 0.00000 0.00000" xyz="-0.00000 -0.00510 0.06940"/>
      <geometry>
        <box size="0.33312 0.10702 0.35498"/>
      </geometry>
    </collision>
    <visual name="torso">
      <origin rpy="0.00000 0.00000 0.00000" xyz="0.00000 -0.00000 0.00000"/>
      <material name="ABS (White)"/>
      <geometry>
        <mesh filename="package://wattson_description/meshes/stl/torso.stl" scale="1.00000 1.00000 1.00000"/>
      </geometry>
    </visual>
  </link>
  <material name="ABS (White)">
    <color rgba="0.96471 0.96471 0.95294 1.00000"/>
  </material>
  <material name="Opaque(160,160,160)">
    <color rgba="0.62745 0.62745 0.62745 1.00000"/>
  </material>
  <material name="Opaque(179,179,179)">
    <color rgba="0.70196 0.70196 0.70196 1.00000"/>
  </material>
  <material name="Opaque(191,189,187)">
    <color rgba="0.74902 0.74118 0.73333 1.00000"/>
  </material>
  <material name="Opaque(25,25,25)">
    <color rgba="0.09804 0.09804 0.09804 1.00000"/>
  </material>
  <material name="Plastic - Matte (White)">
    <color rgba="0.96471 0.96471 0.95294 1.00000"/>
  </material>
  <material name="Plastic - Texture - Random (Black Gloss)">
    <color rgba="0.18431 0.18431 0.18431 1.00000"/>
  </material>
  <material name="Right arrow">
    <color rgba="0.00392 0.00000 0.80000 1.00000"/>
  </material>
  <material name="Stainless Steel - Satin">
    <color rgba="0.79608 0.79608 0.79608 1.00000"/>
  </material>
</robot>