<robot name="elrik" version="1.0">
  <joint name="world_joint" type="fixed">
      <origin xyz="0 0 0.964145" rpy="0 0 0"/>  <!-- 0.964145 is the height of the robot from its origin -->
      <parent link="world"/>
      <child link="link_torso"/>
  </joint>
  <link name="world"/>

  <joint name="joint_head_pitch" type="revolute">
    <limit lower="-3.14000" upper="3.14000" effort="0.00000" velocity="0.00000"/>
    <origin rpy="-0.00000 1.57080 0.00000" xyz="0.00012 0.00000 0.03998"/>
    <parent link="link_head_yaw"/>
    <child link="link_head_pitch"/>
    <axis xyz="0.00000 0.00000 1.00000"/>
  </joint>
  <joint name="joint_head_roll" type="revolute">
    <limit lower="-3.14000" upper="3.14000" effort="0.00000" velocity="0.00000"/>
    <origin rpy="1.57080 -1.57080 0.00000" xyz="-0.10002 0.01200 0.00030"/>
    <parent link="link_head_pitch"/>
    <child link="link_head_roll"/>
    <axis xyz="0.00000 0.00000 1.00000"/>
  </joint>
  <joint name="joint_head_yaw" type="revolute">
    <limit lower="-3.14000" upper="3.14000" effort="0.00000" velocity="0.00000"/>
    <origin rpy="0.00000 0.00000 0.00000" xyz="-0.00012 -0.00000 0.20400"/>
    <parent link="link_torso"/>
    <child link="link_head_yaw"/>
    <axis xyz="0.00000 0.00000 1.00000"/>
  </joint>
  <joint name="joint_left_arm_yaw" type="revolute">
    <limit lower="-3.14000" upper="3.14000" effort="0.00000" velocity="0.00000"/>
    <origin rpy="-1.57080 0.00000 3.14159" xyz="0.00020 -0.12745 0.01486"/>
    <parent link="link_left_shoulder_x"/>
    <child link="link_left_upper_arm"/>
    <axis xyz="0.00000 0.00000 -1.00000"/>
  </joint>
  <joint name="joint_left_elbow_pitch" type="revolute">
    <limit lower="-3.14000" upper="3.14000" effort="0.00000" velocity="0.00000"/>
    <origin rpy="3.14159 -1.57080 3.14159" xyz="0.00011 0.00027 0.23600"/>
    <parent link="link_left_upper_arm"/>
    <child link="link_left_forearm"/>
    <axis xyz="0.00000 0.00000 -1.00000"/>
  </joint>
  <joint name="joint_left_forearm_yaw" type="revolute">
    <limit lower="-3.14000" upper="3.14000" effort="0.00000" velocity="0.00000"/>
    <origin rpy="-3.14159 -1.57080 0.00000" xyz="0.09363 -0.00002 0.00011"/>
    <parent link="link_left_forearm"/>
    <child link="link_left_wrist"/>
    <axis xyz="0.00000 0.00000 -1.00000"/>
  </joint>
  <joint name="joint_left_shoulder_pitch" type="revolute">
    <limit lower="-3.14000" upper="3.14000" effort="0.00000" velocity="0.00000"/>
    <origin rpy="0.00000 1.04720 0.00000" xyz="0.16356 -0.00077 0.19342"/>
    <parent link="link_torso"/>
    <child link="link_left_shoulder"/>
    <axis xyz="0.00000 0.00000 -1.00000"/>
  </joint>
  <joint name="joint_left_shoulder_roll" type="revolute">
    <limit lower="-3.14000" upper="3.14000" effort="0.00000" velocity="0.00000"/>
    <origin rpy="1.57080 -1.04720 -0.00000" xyz="-0.00011 0.00077 0.10785"/>
    <parent link="link_left_shoulder"/>
    <child link="link_left_shoulder_x"/>
    <axis xyz="0.00000 0.00000 1.00000"/>
  </joint>
  <joint name="joint_left_wrist_pitch" type="revolute">
    <limit lower="-3.14000" upper="3.14000" effort="0.00000" velocity="0.00000"/>
    <origin rpy="1.43744 -1.57080 1.70415" xyz="-0.00110 -0.00019 0.17400"/>
    <parent link="link_left_wrist"/>
    <child link="link_left_wrist_x"/>
    <axis xyz="0.00000 0.00000 -1.00000"/>
  </joint>
  <joint name="joint_left_wrist_roll" type="revolute">
    <limit lower="-3.14000" upper="3.14000" effort="0.00000" velocity="0.00000"/>
    <origin rpy="1.57080 -1.57080 0.00000" xyz="0.00002 -0.02290 -0.00009"/>
    <parent link="link_left_wrist_x"/>
    <child link="link_left_hand"/>
    <axis xyz="0.00000 0.00000 1.00000"/>
  </joint>
  <joint name="joint_right_arm_yaw" type="revolute">
    <limit lower="-3.14000" upper="3.14000" effort="0.00000" velocity="0.00000"/>
    <origin rpy="1.57080 -0.00000 0.00000" xyz="-0.00020 -0.12745 0.01486"/>
    <parent link="link_right_shoulder_x"/>
    <child link="link_right_upper_arm"/>
    <axis xyz="0.00000 0.00000 1.00000"/>
  </joint>
  <joint name="joint_right_elbow_pitch" type="revolute">
    <limit lower="-3.14000" upper="3.14000" effort="0.00000" velocity="0.00000"/>
    <origin rpy="1.79848 1.57080 -1.34311" xyz="0.00011 -0.00027 0.23600"/>
    <parent link="link_right_upper_arm"/>
    <child link="link_right_forearm"/>
    <axis xyz="0.00000 0.00000 1.00000"/>
  </joint>
  <joint name="joint_right_forearm_yaw" type="revolute">
    <limit lower="-3.14000" upper="3.14000" effort="0.00000" velocity="0.00000"/>
    <origin rpy="3.14159 1.57080 0.00000" xyz="-0.09363 -0.00002 0.00011"/>
    <parent link="link_right_forearm"/>
    <child link="link_right_wrist"/>
    <axis xyz="0.00000 0.00000 1.00000"/>
  </joint>
  <joint name="joint_right_shoulder_pitch" type="revolute">
    <limit lower="-3.14000" upper="3.14000" effort="0.00000" velocity="0.00000"/>
    <origin rpy="0.00000 0.00000 0.00000" xyz="-0.16356 -0.00077 0.19342"/>
    <parent link="link_torso"/>
    <child link="link_right_shoulder"/>
    <axis xyz="-0.86603 0.00000 0.50000"/>
  </joint>
  <joint name="joint_right_shoulder_roll" type="revolute">
    <limit lower="-3.14000" upper="3.14000" effort="0.00000" velocity="0.00000"/>
    <origin rpy="1.57080 0.00000 -0.00000" xyz="-0.09335 0.00077 0.05402"/>
    <parent link="link_right_shoulder"/>
    <child link="link_right_shoulder_x"/>
    <axis xyz="0.00000 0.00000 -1.00000"/>
  </joint>
  <joint name="joint_right_wrist_pitch" type="revolute">
    <limit lower="-3.14000" upper="3.14000" effort="0.00000" velocity="0.00000"/>
    <origin rpy="-1.79848 1.57080 1.34311" xyz="0.00110 -0.00019 0.17400"/>
    <parent link="link_right_wrist"/>
    <child link="link_right_wrist_x"/>
    <axis xyz="0.00000 0.00000 1.00000"/>
  </joint>
  <joint name="joint_right_wrist_roll" type="revolute">
    <limit lower="-3.14000" upper="3.14000" effort="0.00000" velocity="0.00000"/>
    <origin rpy="1.57080 1.57080 0.00000" xyz="-0.00000 0.00000 -0.00000"/>
    <parent link="link_right_wrist_x"/>
    <child link="link_right_hand"/>
    <axis xyz="0.00000 0.00000 -1.00000"/>
  </joint>
  <link name="link_head_pitch">
    <collision name="head_pitch_collision">
      <origin rpy="0.00000 -1.57080 0.00000" xyz="-0.05327 0.01505 -0.00120"/>
      <geometry>
        <box size="0.05500 0.06310 0.13950"/>
      </geometry>
    </collision>
    <inertial>
      <inertia ixx="0.00039" ixy="0.00000" ixz="-0.00000" iyy="0.00037" iyz="0.00000" izz="0.00012"/>
      <origin rpy="0.00000 0.00000 0.00000" xyz="0.00000 0.00000 0.00000"/>
      <mass value="0.20000"/>
    </inertial>
    <visual name="head_pitch">
      <origin rpy="0.00000 -1.57080 0.00000" xyz="0.00000 0.00000 0.00000"/>
      <material name="Opaque(160,160,160)"/>
      <geometry>
        <mesh filename="package://elrik_description/meshes/stl/head_pitch.stl" scale="1.00000 1.00000 1.00000"/>
      </geometry>
    </visual>
  </link>
  <link name="link_head_roll">
    <collision name="camera_collision">
      <origin rpy="-1.57080 0.00000 0.00000" xyz="0.00845 0.03060 0.05113"/>
      <geometry>
        <box size="0.12520 0.03016 0.02662"/>
      </geometry>
    </collision>
    <collision name="head_roll_collision">
      <origin rpy="-1.57080 0.00000 0.00000" xyz="0.00000 0.00035 0.02365"/>
      <geometry>
        <box size="0.08500 0.05150 0.03370"/>
      </geometry>
    </collision>
    <inertial>
      <inertia ixx="0.00006" ixy="0.00000" ixz="0.00000" iyy="0.00014" iyz="0.00000" izz="0.00016"/>
      <origin rpy="0.00000 0.00000 0.00000" xyz="0.00000 -0.00000 -0.00000"/>
      <mass value="0.20000"/>
    </inertial>
    <visual name="camera">
      <origin rpy="-1.57080 0.00000 0.00000" xyz="0.00620 0.03059 0.03605"/>
      <material name="Plastic - Texture - Random (Yellow)"/>
      <geometry>
        <mesh filename="package://elrik_description/meshes/stl/camera.stl" scale="1.00000 1.00000 1.00000"/>
      </geometry>
    </visual>
    <visual name="head_roll">
      <origin rpy="-1.57080 0.00000 0.00000" xyz="0.00000 -0.00000 -0.00000"/>
      <material name="Opaque(160,160,160)"/>
      <geometry>
        <mesh filename="package://elrik_description/meshes/stl/head_roll.stl" scale="1.00000 1.00000 1.00000"/>
      </geometry>
    </visual>
  </link>
  <link name="link_head_yaw">
    <collision name="head_yaw_collision">
      <origin rpy="0.00000 0.00000 0.00000" xyz="-0.00058 0.00850 0.03150"/>
      <geometry>
        <box size="0.04200 0.06300 0.06300"/>
      </geometry>
    </collision>
    <inertial>
      <inertia ixx="0.00013" ixy="0.00000" ixz="0.00000" iyy="0.00010" iyz="0.00000" izz="0.00010"/>
      <origin rpy="0.00000 0.00000 0.00000" xyz="-0.00000 0.00000 0.00000"/>
      <mass value="0.20000"/>
    </inertial>
    <visual name="head_yaw">
      <origin rpy="0.00000 0.00000 0.00000" xyz="-0.00000 0.00000 0.00000"/>
      <material name="Opaque(25,25,25)"/>
      <geometry>
        <mesh filename="package://elrik_description/meshes/stl/head_yaw.stl" scale="1.00000 1.00000 1.00000"/>
      </geometry>
    </visual>
  </link>
  <link name="link_left_forearm">
    <collision name="left_forearm_collision">
      <origin rpy="0.00000 -1.57080 0.00000" xyz="0.03558 0.00583 -0.00393"/>
      <geometry>
        <box size="0.08489 0.06853 0.11616"/>
      </geometry>
    </collision>
    <inertial>
      <inertia ixx="0.00030" ixy="0.00000" ixz="-0.00000" iyy="0.00034" iyz="0.00000" izz="0.00020"/>
      <origin rpy="0.00000 0.00000 0.00000" xyz="-0.00000 0.00000 0.00000"/>
      <mass value="0.20000"/>
    </inertial>
    <visual name="left_forearm">
      <origin rpy="0.00000 -1.57080 0.00000" xyz="-0.00000 0.00000 0.00000"/>
      <material name="Opaque(25,25,25)"/>
      <geometry>
        <mesh filename="package://elrik_description/meshes/stl/left_forearm.stl" scale="1.00000 1.00000 1.00000"/>
      </geometry>
    </visual>
  </link>
  <link name="link_left_hand">
    <collision name="left_hand_collision">
      <origin rpy="-1.57080 0.00000 0.00000" xyz="-0.00054 -0.11191 -0.03097"/>
      <geometry>
        <box size="0.05243 0.08957 0.26082"/>
      </geometry>
    </collision>
    <inertial>
      <inertia ixx="0.00127" ixy="0.00000" ixz="0.00000" iyy="0.00154" iyz="0.00000" izz="0.00054"/>
      <origin rpy="0.00000 0.00000 0.00000" xyz="0.00000 0.00000 0.00000"/>
      <mass value="0.20000"/>
    </inertial>
    <visual name="left_hand">
      <origin rpy="-1.57080 0.00000 0.00000" xyz="-0.00000 0.00000 0.00000"/>
      <material name="Opaque(160,160,160)"/>
      <geometry>
        <mesh filename="package://elrik_description/meshes/stl/left_hand.stl" scale="1.00000 1.00000 1.00000"/>
      </geometry>
    </visual>
  </link>
  <link name="link_left_shoulder">
    <collision name="left_shoulder_collision">
      <origin rpy="0.00000 0.00000 1.57080" xyz="0.00517 0.00077 0.07398"/>
      <geometry>
        <cylinder radius="0.05019" length="0.12980"/>
      </geometry>
    </collision>
    <inertial>
      <inertia ixx="0.00068" ixy="0.00000" ixz="0.00000" iyy="0.00068" iyz="0.00000" izz="0.00065"/>
      <origin rpy="0.00000 0.00000 0.00000" xyz="0.00000 -0.00000 0.00000"/>
      <mass value="0.20000"/>
    </inertial>
    <visual name="left_shoulder">
      <origin rpy="0.00000 -1.04720 -0.00000" xyz="0.00000 -0.00000 -0.00000"/>
      <material name="Opaque(25,25,25)"/>
      <geometry>
        <mesh filename="package://elrik_description/meshes/stl/left_shoulder.stl" scale="1.00000 1.00000 1.00000"/>
      </geometry>
    </visual>
  </link>
  <link name="link_left_shoulder_x">
    <collision name="left_shoulder_x_collision">
      <origin rpy="-1.57080 0.00000 0.00000" xyz="0.00020 -0.05428 0.00895"/>
      <geometry>
        <box size="0.06396 0.10018 0.17240"/>
      </geometry>
    </collision>
    <inertial>
      <inertia ixx="0.00066" ixy="0.00000" ixz="0.00000" iyy="0.00056" iyz="0.00000" izz="0.00024"/>
      <origin rpy="0.00000 0.00000 0.00000" xyz="0.00000 0.00000 0.00000"/>
      <mass value="0.20000"/>
    </inertial>
    <visual name="left_shoulder_x">
      <origin rpy="-1.57080 0.00000 0.00000" xyz="0.00000 0.00000 -0.00000"/>
      <material name="Opaque(179,179,179)"/>
      <geometry>
        <mesh filename="package://elrik_description/meshes/stl/left_shoulder_x.stl" scale="1.00000 1.00000 1.00000"/>
      </geometry>
    </visual>
  </link>
  <link name="link_left_upper_arm">
    <collision name="left_upper_arm_collision">
      <origin rpy="3.14159 0.00000 3.14159" xyz="0.00473 0.00127 0.13299"/>
      <geometry>
        <box size="0.07946 0.06203 0.26602"/>
      </geometry>
    </collision>
    <inertial>
      <inertia ixx="0.00124" ixy="0.00000" ixz="0.00000" iyy="0.00128" iyz="0.00000" izz="0.00017"/>
      <origin rpy="0.00000 0.00000 0.00000" xyz="0.00000 0.00000 -0.00000"/>
      <mass value="0.20000"/>
    </inertial>
    <visual name="left_upper_arm">
      <origin rpy="3.14159 0.00000 3.14159" xyz="0.00000 0.00000 -0.00000"/>
      <material name="Opaque(191,189,187)"/>
      <geometry>
        <mesh filename="package://elrik_description/meshes/stl/left_upper_arm.stl" scale="1.00000 1.00000 1.00000"/>
      </geometry>
    </visual>
  </link>
  <link name="link_left_wrist">
    <collision name="left_wrist_collision">
      <origin rpy="3.14159 0.00000 0.00000" xyz="0.00130 -0.00313 0.09773"/>
      <geometry>
        <box size="0.07085 0.08614 0.19550"/>
      </geometry>
    </collision>
    <inertial>
      <inertia ixx="0.00076" ixy="0.00000" ixz="0.00000" iyy="0.00072" iyz="-0.00000" izz="0.00021"/>
      <origin rpy="0.00000 0.00000 0.00000" xyz="0.00000 0.00000 -0.00000"/>
      <mass value="0.20000"/>
    </inertial>
    <visual name="left_wrist">
      <origin rpy="3.14159 0.00000 0.00000" xyz="0.00000 -0.00000 -0.00000"/>
      <material name="Opaque(160,160,160)"/>
      <geometry>
        <mesh filename="package://elrik_description/meshes/stl/left_wrist.stl" scale="1.00000 1.00000 1.00000"/>
      </geometry>
    </visual>
  </link>
  <link name="link_left_wrist_x">
    <collision name="left_wrist_x_collision">
      <origin rpy="-0.00000 -1.57080 0.00000" xyz="-0.00775 0.00002 0.00201"/>
      <geometry>
        <box size="0.07164 0.08000 0.06454"/>
      </geometry>
    </collision>
    <inertial>
      <inertia ixx="0.00018" ixy="0.00000" ixz="0.00000" iyy="0.00015" iyz="0.00000" izz="0.00019"/>
      <origin rpy="0.00000 0.00000 0.00000" xyz="-0.00000 0.00000 0.00000"/>
      <mass value="0.20000"/>
    </inertial>
    <visual name="left_wrist_x">
      <origin rpy="-0.00000 -1.57080 0.00000" xyz="0.00000 0.00000 0.00000"/>
      <material name="Opaque(25,25,25)"/>
      <geometry>
        <mesh filename="package://elrik_description/meshes/stl/left_wrist_x.stl" scale="1.00000 1.00000 1.00000"/>
      </geometry>
    </visual>
  </link>
  <link name="link_right_forearm">
    <collision name="right_forearm_collision">
      <origin rpy="-0.00000 1.57080 0.00000" xyz="-0.03558 0.00583 -0.00393"/>
      <geometry>
        <box size="0.08489 0.06853 0.11616"/>
      </geometry>
    </collision>
    <inertial>
      <inertia ixx="0.00030" ixy="0.00000" ixz="0.00000" iyy="0.00034" iyz="0.00000" izz="0.00020"/>
      <origin rpy="0.00000 0.00000 0.00000" xyz="-0.00000 -0.00000 -0.00000"/>
      <mass value="0.20000"/>
    </inertial>
    <visual name="right_forearm">
      <origin rpy="-0.00000 1.57080 0.00000" xyz="0.00000 -0.00000 -0.00000"/>
      <material name="Opaque(25,25,25)"/>
      <geometry>
        <mesh filename="package://elrik_description/meshes/stl/right_forearm.stl" scale="1.00000 1.00000 1.00000"/>
      </geometry>
    </visual>
  </link>
  <link name="link_right_hand">
    <collision name="right_hand_collision">
      <origin rpy="-1.57080 -0.00000 0.00000" xyz="0.00016 -0.11193 -0.00807"/>
      <geometry>
        <box size="0.04897 0.08957 0.26082"/>
      </geometry>
    </collision>
    <inertial>
      <inertia ixx="0.00127" ixy="0.00000" ixz="-0.00000" iyy="0.00154" iyz="-0.00000" izz="0.00054"/>
      <origin rpy="0.00000 0.00000 0.00000" xyz="0.00009 -0.00002 0.02290"/>
      <mass value="0.20000"/>
    </inertial>
    <visual name="right_hand">
      <origin rpy="-1.57080 0.00000 0.00000" xyz="0.00009 -0.00002 0.02290"/>
      <material name="Opaque(160,160,160)"/>
      <geometry>
        <mesh filename="package://elrik_description/meshes/stl/right_hand.stl" scale="1.00000 1.00000 1.00000"/>
      </geometry>
    </visual>
  </link>
  <link name="link_right_shoulder">
    <collision name="right_shoulder_collision">
      <origin rpy="2.08657 -0.01930 1.47639" xyz="-0.06662 0.00167 0.03240"/>
      <geometry>
        <cylinder radius="0.04602" length="0.13522"/>
      </geometry>
    </collision>
    <inertial>
      <inertia ixx="0.00068" ixy="0.00000" ixz="-0.00000" iyy="0.00068" iyz="0.00000" izz="0.00065"/>
      <origin rpy="0.00000 0.00000 0.00000" xyz="-0.00000 0.00000 0.00000"/>
      <mass value="0.20000"/>
    </inertial>
    <visual name="right_shoulder">
      <origin rpy="-0.00000 0.00000 0.00000" xyz="-0.00000 0.00000 0.00000"/>
      <material name="Opaque(25,25,25)"/>
      <geometry>
        <mesh filename="package://elrik_description/meshes/stl/right_shoulder.stl" scale="1.00000 1.00000 1.00000"/>
      </geometry>
    </visual>
  </link>
  <link name="link_right_shoulder_x">
    <collision name="right_shoulder_x_collision">
      <origin rpy="-1.57080 -0.00000 0.00000" xyz="-0.00020 -0.05428 0.00895"/>
      <geometry>
        <box size="0.06396 0.10018 0.17240"/>
      </geometry>
    </collision>
    <inertial>
      <inertia ixx="0.00066" ixy="0.00000" ixz="0.00000" iyy="0.00056" iyz="-0.00000" izz="0.00024"/>
      <origin rpy="0.00000 0.00000 0.00000" xyz="0.00000 0.00000 -0.00000"/>
      <mass value="0.20000"/>
    </inertial>
    <visual name="right_shoulder_x">
      <origin rpy="-1.57080 0.00000 0.00000" xyz="0.00000 0.00000 -0.00000"/>
      <material name="Opaque(179,179,179)"/>
      <geometry>
        <mesh filename="package://elrik_description/meshes/stl/right_shoulder_x.stl" scale="1.00000 1.00000 1.00000"/>
      </geometry>
    </visual>
  </link>
  <link name="link_right_upper_arm">
    <collision name="right_upper_arm_collision">
      <origin rpy="3.14159 -0.00000 -0.00000" xyz="0.00473 -0.00127 0.13299"/>
      <geometry>
        <box size="0.07946 0.06203 0.26602"/>
      </geometry>
    </collision>
    <inertial>
      <inertia ixx="0.00124" ixy="-0.00000" ixz="-0.00000" iyy="0.00128" iyz="-0.00000" izz="0.00017"/>
      <origin rpy="0.00000 0.00000 0.00000" xyz="0.00000 0.00000 -0.00000"/>
      <mass value="0.20000"/>
    </inertial>
    <visual name="right_upper_arm">
      <origin rpy="3.14159 -0.00000 0.00000" xyz="0.00000 0.00000 -0.00000"/>
      <material name="Opaque(191,189,187)"/>
      <geometry>
        <mesh filename="package://elrik_description/meshes/stl/right_upper_arm.stl" scale="1.00000 1.00000 1.00000"/>
      </geometry>
    </visual>
  </link>
  <link name="link_right_wrist">
    <collision name="right_wrist_collision">
      <origin rpy="-3.14159 -0.00000 0.00000" xyz="-0.00130 -0.00313 0.09773"/>
      <geometry>
        <box size="0.07085 0.08614 0.19550"/>
      </geometry>
    </collision>
    <inertial>
      <inertia ixx="0.00076" ixy="-0.00000" ixz="-0.00000" iyy="0.00072" iyz="0.00000" izz="0.00021"/>
      <origin rpy="0.00000 0.00000 0.00000" xyz="0.00000 0.00000 0.00000"/>
      <mass value="0.20000"/>
    </inertial>
    <visual name="right_wrist">
      <origin rpy="-3.14159 0.00000 0.00000" xyz="0.00000 0.00000 0.00000"/>
      <material name="Opaque(160,160,160)"/>
      <geometry>
        <mesh filename="package://elrik_description/meshes/stl/right_wrist.stl" scale="1.00000 1.00000 1.00000"/>
      </geometry>
    </visual>
  </link>
  <link name="link_right_wrist_x">
    <collision name="right_wrist_x_collision">
      <origin rpy="-0.00000 1.57080 0.00000" xyz="0.00775 0.00002 0.00201"/>
      <geometry>
        <box size="0.07164 0.08000 0.06454"/>
      </geometry>
    </collision>
    <inertial>
      <inertia ixx="0.00018" ixy="0.00000" ixz="-0.00000" iyy="0.00015" iyz="-0.00000" izz="0.00019"/>
      <origin rpy="0.00000 0.00000 0.00000" xyz="-0.00000 -0.00000 -0.00000"/>
      <mass value="0.20000"/>
    </inertial>
    <visual name="right_wrist_x">
      <origin rpy="-0.00000 1.57080 0.00000" xyz="-0.00000 -0.00000 -0.00000"/>
      <material name="Opaque(25,25,25)"/>
      <geometry>
        <mesh filename="package://elrik_description/meshes/stl/right_wrist_x.stl" scale="1.00000 1.00000 1.00000"/>
      </geometry>
    </visual>
  </link>
  <link name="link_torso">
    <collision name="torso_collision">
      <origin rpy="0.00000 0.00000 0.00000" xyz="0.00000 0.00040 0.10725"/>
      <geometry>
        <box size="0.38548 0.07402 0.25694"/>
      </geometry>
    </collision>
    <inertial>
      <inertia ixx="0.06277" ixy="0.00000" ixz="0.00000" iyy="0.06683" iyz="0.00000" izz="0.04157"/>
      <origin rpy="0.00000 0.00000 0.00000" xyz="0.00000 -0.00000 0.00000"/>
      <mass value="0.20000"/>
    </inertial>
    <visual name="torso">
      <origin rpy="0.00000 0.00000 0.00000" xyz="0.00000 -0.00000 0.00000"/>
      <material name="ABS (White)"/>
      <geometry>
        <mesh filename="package://elrik_description/meshes/stl/torso.stl" scale="1.00000 1.00000 1.00000"/>
      </geometry>
    </visual>
  </link>
  <material name="ABS (White)">
    <color rgba="0.96471 0.96471 0.95294 1.00000"/>
  </material>
  <material name="Opaque(160,160,160)">
    <color rgba="0.62745 0.62745 0.62745 1.00000"/>
  </material>
  <material name="Opaque(179,179,179)">
    <color rgba="0.70196 0.70196 0.70196 1.00000"/>
  </material>
  <material name="Opaque(191,189,187)">
    <color rgba="0.74902 0.74118 0.73333 1.00000"/>
  </material>
  <material name="Opaque(25,25,25)">
    <color rgba="0.09804 0.09804 0.09804 1.00000"/>
  </material>
  <material name="Plastic - Texture - Random (Yellow)">
    <color rgba="1.00000 0.95294 0.31373 1.00000"/>
  </material>
</robot>